Workbook

Sheet 278_FINAL
A1: Chr | B1: Start | C1: End | D1: Ref | E1: Alt | F1: Func.refGene | G1: Gene.refGene | H1: ExonicFunc.refGene | I1: AAChange.refGene | J1: phastConsElements46way | K1: genomicSuperDups | L1: esp6500si_all | M1: 1000g2012apr_all | N1: snp137 | O1: LJB2_SIFT | P1: LJB2_PolyPhen2_HDIV | Q1: LJB2_PP2_HDIV_Pred | R1: LJB2_PolyPhen2_HVAR | S1: LJB2_PolyPhen2_HVAR_Pred | T1: LJB2_LRT | U1: LJB2_LRT_Pred | V1: LJB2_MutationTaster | W1: LJB2_MutationTaster_Pred | X1: LJB_MutationAssessor | Y1: LJB_MutationAssessor_Pred | Z1: LJB2_FATHMM | AA1: LJB2_GERP++ | AB1: LJB2_PhyloP | AC1: LJB2_SiPhy | AD1: CADD_PHRED | AE1: GT | AF1: DP | AG1: Zygosity | AH1: Variant_ID
A2: chr3 | B2: 41275687 | C2: 41275687 | D2: C | E2: T | F2: exonic | G2: CTNNB1 | H2: nonsynonymous SNV | I2: CTNNB1:NM_001098209:exon10:c.C1582T:p.R528C,CTNNB1:NM_001098210:exon10:c.C1582T:p.R528C,CTNNB1:NM_001904:exon10:c.C1582T:p.R528C | J2: Score=686;Name=lod=820 | O2: 0.03 | P2: 1 | Q2: D | R2: 0.98 | S2: D | T2: 0 | U2: D | V2: 0.999995 | W2: D | X2: 3.345 | Y2: medium | Z2: -1.05 | AA2: 5.96 | AB2: 2.832 | AC2: 20.422 | AD2: 33 | AE2: 0/1 | AF2: 84 | AG2: Heterozygous | AH2: =A2&"_"&B2&"_"&D2&"_"&E2 -> chr3_41275687_C_T

Sheet 3347_FINAL
A1: Chr | B1: Start | C1: End | D1: Ref | E1: Alt | F1: Func.refGene | G1: Gene.refGene | H1: ExonicFunc.refGene | I1: AAChange.refGene | J1: phastConsElements46way | K1: genomicSuperDups | L1: esp6500si_all | M1: 1000g2012apr_all | N1: snp137 | O1: LJB2_SIFT | P1: LJB2_PolyPhen2_HDIV | Q1: LJB2_PP2_HDIV_Pred | R1: LJB2_PolyPhen2_HVAR | S1: LJB2_PolyPhen2_HVAR_Pred | T1: LJB2_LRT | U1: LJB2_LRT_Pred | V1: LJB2_MutationTaster | W1: LJB2_MutationTaster_Pred | X1: LJB_MutationAssessor | Y1: LJB_MutationAssessor_Pred | Z1: LJB2_FATHMM | AA1: LJB2_GERP++ | AB1: LJB2_PhyloP | AC1: LJB2_SiPhy | AD1: CADD_PHRED | AE1: GT | AF1: DP | AG1: Zygosity | AH1: Variant ID | AI1: Common hits w/ MM47
A2: chr1 | B2: 6046339 | C2: 6046339 | D2: C | E2: T | F2: exonic | G2: NPHP4 | H2: stopgain SNV | I2: NPHP4:NM_015102:exon2:c.G11A:p.W4X | J2: Score=333;Name=lod=30 | O2: 1 | P2: . | Q2: . | R2: . | S2: . | T2: 2e-06 | U2: D | V2: 1 | W2: A | X2: . | Y2: . | Z2: . | AA2: 5.41 | AB2: 2.687 | AC2: 17.0503 | AD2: 37 | AE2: 0/1 | AF2: 8 | AG2: Heterozygous | AH2: =A2&"_"&B2&"_"&D2&"_"&E2 -> chr1_6046339_C_T | AI2: =IF(ISNUMBER(MATCH(AH2,MM47_FINAL!$AH:$AH,0)),"YES","NO") -> NO
A3: chr1 | B3: 26769270 | C3: 26769270 | D3: G | E3: T | F3: exonic | G3: DHDDS | H3: nonsynonymous SNV | I3: DHDDS:NM_001243564:exon4:c.G229T:p.A77S,DHDDS:NM_001243565:exon4:c.G229T:p.A77S,DHDDS:NM_024887:exon4:c.G229T:p.A77S,DHDDS:NM_205861:exon4:c.G229T:p.A77S | J3: Score=596;Name=lod=353 | O3: 0 | P3: 1 | Q3: D | R3: 1 | S3: D | T3: 0 | U3: D | V3: 0.999977 | W3: D | X3: 3.205 | Y3: medium | Z3: 1.29 | AA3: 5.92 | AB3: 2.809 | AC3: 19.3088 | AD3: 31 | AE3: 0/1 | AF3: 23 | AG3: Heterozygous | AH3: =A3&"_"&B3&"_"&D3&"_"&E3 -> chr1_26769270_G_T | AI3: =IF(ISNUMBER(MATCH(AH3,MM47_FINAL!$AH:$AH,0)),"YES","NO") -> NO
A4: chr1 | B4: 26769294 | C4: 26769294 | D4: C | E4: G | F4: exonic | G4: DHDDS | H4: nonsynonymous SNV | I4: DHDDS:NM_001243564:exon4:c.C253G:p.R85G,DHDDS:NM_001243565:exon4:c.C253G:p.R85G,DHDDS:NM_024887:exon4:c.C253G:p.R85G,DHDDS:NM_205861:exon4:c.C253G:p.R85G | J4: Score=596;Name=lod=353 | O4: 0 | P4: 1 | Q4: D | R4: 1 | S4: D | T4: 0 | U4: D | V4: 0.999996 | W4: D | X4: 4.785 | Y4: high | Z4: -0.66 | AA4: 5.92 | AB4: 2.809 | AC4: 19.3088 | AD4: 33 | AE4: 0/1 | AF4: 18 | AG4: Heterozygous | AH4: =A4&"_"&B4&"_"&D4&"_"&E4 -> chr1_26769294_C_G | AI4: =IF(ISNUMBER(MATCH(AH4,MM47_FINAL!$AH:$AH,0)),"YES","NO") -> NO
A5: chr1 | B5: 26769295 | C5: 26769295 | D5: G | E5: T | F5: exonic | G5: DHDDS | H5: nonsynonymous SNV | I5: DHDDS:NM_001243564:exon4:c.G254T:p.R85L,DHDDS:NM_001243565:exon4:c.G254T:p.R85L,DHDDS:NM_024887:exon4:c.G254T:p.R85L,DHDDS:NM_205861:exon4:c.G254T:p.R85L | J5: Score=596;Name=lod=353 | O5: 0 | P5: 1 | Q5: D | R5: 1 | S5: D | T5: 0 | U5: D | V5: 0.999998 | W5: D | X5: 4.785 | Y5: high | Z5: -0.66 | AA5: 5.92 | AB5: 2.809 | AC5: 19.3088 | AD5: 33 | AE5: 0/1 | AF5: 17 | AG5: Heterozygous | AH5: =A5&"_"&B5&"_"&D5&"_"&E5 -> chr1_26769295_G_T | AI5: =IF(ISNUMBER(MATCH(AH5,MM47_FINAL!$AH:$AH,0)),"YES","NO") -> NO
A6: chr1 | B6: 94508360 | C6: 94508360 | D6: G | E6: C | F6: exonic | G6: ABCA4 | H6: stopgain SNV | I6: ABCA4:NM_000350:exon22:c.C3285G:p.Y1095X | J6: Score=557;Name=lod=244 | O6: 1 | P6: . | Q6: . | R6: . | S6: . | T6: 0 | U6: D | V6: 1 | W6: A | X6: . | Y6: . | Z6: . | AA6: 1.31 | AB6: 0.369 | AC6: 9.8067 | AD6: 35 | AE6: 0/1 | AF6: 27 | AG6: Heterozygous | AH6: =A6&"_"&B6&"_"&D6&"_"&E6 -> chr1_94508360_G_C | AI6: =IF(ISNUMBER(MATCH(AH6,MM47_FINAL!$AH:$AH,0)),"YES","NO") -> NO
A7: chr1 | B7: 94528171 | C7: 94528171 | D7: G | E7: C | F7: exonic | G7: ABCA4 | H7: stopgain SNV | I7: ABCA4:NM_000350:exon13:c.C1899G:p.Y633X | J7: Score=584;Name=lod=314 | O7: 1 | P7: . | Q7: . | R7: . | S7: . | T7: 0 | U7: D | V7: 1 | W7: A | X7: . | Y7: . | Z7: . | AA7: -2.67 | AB7: -0.692 | AC7: 12.3139 | AD7: 36 | AE7: 0/1 | AF7: 8 | AG7: Heterozygous | AH7: =A7&"_"&B7&"_"&D7&"_"&E7 -> chr1_94528171_G_C | AI7: =IF(ISNUMBER(MATCH(AH7,MM47_FINAL!$AH:$AH,0)),"YES","NO") -> NO
A8: chr1 | B8: 110146013 | C8: 110146013 | D8: A | E8: T | F8: exonic | G8: GNAT2 | H8: nonsynonymous SNV | I8: GNAT2:NM_005272:exon8:c.T1028A:p.I343N | J8: Score=724;Name=lod=1171 | O8: 0 | P8: 0.998 | Q8: D | R8: 0.992 | S8: D | T8: 0 | U8: D | V8: 0.999703 | W8: D | X8: 4.24 | Y8: high | Z8: -2.54 | AA8: 5.48 | AB8: 2.205 | AC8: 15.5478 | AD8: 32 | AE8: 0/1 | AF8: 6 | AG8: Heterozygous | AH8: =A8&"_"&B8&"_"&D8&"_"&E8 -> chr1_110146013_A_T | AI8: =IF(ISNUMBER(MATCH(AH8,MM47_FINAL!$AH:$AH,0)),"YES","NO") -> NO
A9: chr1 | B9: 150300866 | C9: 150300866 | D9: G | E9: T | F9: exonic | G9: PRPF3 | H9: stopgain SNV | I9: PRPF3:NM_004698:exon4:c.G364T:p.E122X | J9: Score=482;Name=lod=121 | O9: 0.65 | P9: . | Q9: . | R9: . | S9: . | T9: 7e-06 | U9: D | V9: 1 | W9: A | X9: . | Y9: . | Z9: . | AA9: 5.91 | AB9: 2.802 | AC9: 19.8933 | AD9: 39 | AE9: 0/1 | AF9: 10 | AG9: Heterozygous | AH9: =A9&"_"&B9&"_"&D9&"_"&E9 -> chr1_150300866_G_T | AI9: =IF(ISNUMBER(MATCH(AH9,MM47_FINAL!$AH:$AH,0)),"YES","NO") -> NO
A10: chr1 | B10: 150307650 | C10: 150307650 | D10: C | E10: T | F10: exonic | G10: PRPF3 | H10: nonsynonymous SNV | I10: PRPF3:NM_004698:exon7:c.C973T:p.R325C | J10: Score=549;Name=lod=227 | O10: 0 | P10: 1 | Q10: D | R10: 0.998 | S10: D | T10: 2e-06 | U10: D | V10: 0.995791 | W10: D | X10: 3.565 | Y10: high | Z10: -2.19 | AA10: 5.63 | AB10: 2.808 | AC10: 14.8476 | AD10: 33 | AE10: 0/1 | AF10: 9 | AG10: Heterozygous | AH10: =A10&"_"&B10&"_"&D10&"_"&E10 -> chr1_150307650_C_T | AI10: =IF(ISNUMBER(MATCH(AH10,MM47_FINAL!$AH:$AH,0)),"YES","NO") -> NO
A11: chr2 | B11: 27700166 | C11: 27700166 | D11: C | E11: T | F11: exonic | G11: IFT172 | H11: nonsynonymous SNV | I11: IFT172:NM_015662:exon13:c.G1243A:p.G415R | J11: Score=538;Name=lod=204 | O11: 0 | P11: 1 | Q11: D | R11: 0.992 | S11: D | T11: 0 | U11: D | V11: 0.999984 | W11: D | X11: 3.11 | Y11: medium | Z11: 2.59 | AA11: 5.83 | AB11: 2.758 | AC11: 18.6658 | AD11: 32 | AE11: 0/1 | AF11: 19 | AG11: Heterozygous | AH11: =A11&"_"&B11&"_"&D11&"_"&E11 -> chr2_27700166_C_T | AI11: =IF(ISNUMBER(MATCH(AH11,MM47_FINAL!$AH:$AH,0)),"YES","NO") -> NO
A12: chr2 | B12: 73675671 | C12: 73675671 | D12: G | E12: T | F12: exonic | G12: ALMS1 | H12: stopgain SNV | I12: ALMS1:NM_015120:exon8:c.G2014T:p.E672X | O12: 0.25 | P12: . | Q12: . | R12: . | S12: . | T12: 0.009115 | U12: N | V12: 1 | W12: A | X12: . | Y12: . | Z12: . | AA12: 3.24 | AB12: 1.33 | AC12: 7.858 | AD12: 32 | AE12: 0/1 | AF12: 16 | AG12: Heterozygous | AH12: =A12&"_"&B12&"_"&D12&"_"&E12 -> chr2_73675671_G_T | AI12: =IF(ISNUMBER(MATCH(AH12,MM47_FINAL!$AH:$AH,0)),"YES","NO") -> NO
A13: chr2 | B13: 96940818 | C13: 96940818 | D13: C | E13: T | F13: exonic | G13: SNRNP200 | H13: nonsynonymous SNV | I13: SNRNP200:NM_014014:exon45:c.G6343A:p.G2115R | J13: Score=545;Name=lod=218 | O13: 0 | P13: 1 | Q13: D | R13: 0.999 | S13: D | T13: 0 | U13: D | V13: 0.999995 | W13: D | X13: 3.735 | Y13: high | Z13: -0.71 | AA13: 5.49 | AB13: 2.592 | AC13: 16.9638 | AD13: 31 | AE13: 0/1 | AF13: 7 | AG13: Heterozygous | AH13: =A13&"_"&B13&"_"&D13&"_"&E13 -> chr2_96940818_C_T | AI13: =IF(ISNUMBER(MATCH(AH13,MM47_FINAL!$AH:$AH,0)),"YES","NO") -> NO
A14: chr2 | B14: 96959142 | C14: 96959142 | D14: C | E14: A | F14: exonic | G14: SNRNP200 | H14: nonsynonymous SNV | I14: SNRNP200:NM_014014:exon15:c.G1948T:p.G650C | J14: Score=659;Name=lod=634 | O14: 0 | P14: 1 | Q14: D | R14: 0.998 | S14: D | T14: 0 | U14: D | V14: 0.999998 | W14: D | X14: 3.48 | Y14: medium | Z14: 0.88 | AA14: 6.17 | AB14: 2.941 | AC14: 19.6509 | AD14: 33 | AE14: 0/1 | AF14: 9 | AG14: Heterozygous | AH14: =A14&"_"&B14&"_"&D14&"_"&E14 -> chr2_96959142_C_A | AI14: =IF(ISNUMBER(MATCH(AH14,MM47_FINAL!$AH:$AH,0)),"YES","NO") -> NO
A15: chr2 | B15: 97462830 | C15: 97462830 | D15: C | E15: T | F15: exonic | G15: CNNM4 | H15: nonsynonymous SNV | I15: CNNM4:NM_020184:exon2:c.C1484T:p.T495I | J15: Score=623;Name=lod=454 | O15: 0 | P15: 1 | Q15: D | R15: 1 | S15: D | T15: 0 | U15: D | V15: 0.998976 | W15: D | X15: 4.35 | Y15: high | Z15: -3.79 | AA15: 5.1 | AB15: 2.546 | AC15: 17.6409 | AD15: 32 | AE15: 1/1 | AF15: 1 | AG15: Homozygous_alt | AH15: =A15&"_"&B15&"_"&D15&"_"&E15 -> chr2_97462830_C_T | AI15: =IF(ISNUMBER(MATCH(AH15,MM47_FINAL!$AH:$AH,0)),"YES","NO") -> NO
A16: chr2 | B16: 234969123 | C16: 234969123 | D16: G | E16: T | F16: exonic | G16: SPP2 | H16: nonsynonymous SNV | I16: SPP2:NM_006944:exon4:c.G444T:p.E148D | J16: Score=381;Name=lod=47 | O16: 0.04 | P16: 0.999 | Q16: D | R16: 0.997 | S16: D | T16: 0 | U16: D | V16: . | W16: . | X16: 2.19 | Y16: medium | Z16: 0.42 | AA16: 5.28 | AB16: 2.454 | AC16: 14.4284 | AD16: 32 | AE16: 0/1 | AF16: 11 | AG16: Heterozygous | AH16: =A16&"_"&B16&"_"&D16&"_"&E16 -> chr2_234969123_G_T | AI16: =IF(ISNUMBER(MATCH(AH16,MM47_FINAL!$AH:$AH,0)),"YES","NO") -> NO
A17: chr3 | B17: 14509690 | C17: 14509690 | D17: G | E17: T | F17: exonic | G17: SLC6A6 | H17: nonsynonymous SNV | I17: SLC6A6:NM_001134367:exon9:c.G1066T:p.G356C,SLC6A6:NM_003043:exon9:c.G1066T:p.G356C | J17: Score=767;Name=lod=1753 | O17: 0 | P17: 1 | Q17: D | R17: 1 | S17: D | T17: 1e-06 | U17: D | V17: 0.994219 | W17: D | X17: 4.11 | Y17: high | Z17: -1.07 | AA17: 5 | AB17: 2.311 | AC17: 18.2995 | AD17: 33 | AE17: 1/1 | AF17: 1 | AG17: Homozygous_alt | AH17: =A17&"_"&B17&"_"&D17&"_"&E17 -> chr3_14509690_G_T | AI17: =IF(ISNUMBER(MATCH(AH17,MM47_FINAL!$AH:$AH,0)),"YES","NO") -> NO
A18: chr3 | B18: 14509691 | C18: 14509691 | D18: G | E18: A | F18: exonic | G18: SLC6A6 | H18: nonsynonymous SNV | I18: SLC6A6:NM_001134367:exon9:c.G1067A:p.G356D,SLC6A6:NM_003043:exon9:c.G1067A:p.G356D | J18: Score=767;Name=lod=1753 | O18: 0.01 | P18: 0.999 | Q18: D | R18: 0.989 | S18: D | T18: 1e-06 | U18: D | V18: 0.983687 | W18: D | X18: 2.76 | Y18: medium | Z18: -0.94 | AA18: 5 | AB18: 2.311 | AC18: 18.2995 | AD18: 31 | AE18: 1/1 | AF18: 1 | AG18: Homozygous_alt | AH18: =A18&"_"&B18&"_"&D18&"_"&E18 -> chr3_14509691_G_A | AI18: =IF(ISNUMBER(MATCH(AH18,MM47_FINAL!$AH:$AH,0)),"YES","NO") -> NO
A19: chr3 | B19: 27439188 | C19: 27439188 | D19: G | E19: T | F19: exonic | G19: SLC4A7 | H19: nonsynonymous SNV | I19: SLC4A7:NM_001258379:exon17:c.C2306A:p.P769H,SLC4A7:NM_001258380:exon17:c.C2291A:p.P764H,SLC4A7:NM_003615:exon18:c.C2663A:p.P888H | J19: Score=644;Name=lod=551 | O19: 0 | P19: 1 | Q19: D | R19: 1 | S19: D | T19: 0 | U19: D | V19: 0.999751 | W19: D | X19: 3.3 | Y19: medium | Z19: -3.32 | AA19: 5.71 | AB19: 2.712 | AC19: 19.9139 | AD19: 32 | AE19: 0/1 | AF19: 13 | AG19: Heterozygous | AH19: =A19&"_"&B19&"_"&D19&"_"&E19 -> chr3_27439188_G_T | AI19: =IF(ISNUMBER(MATCH(AH19,MM47_FINAL!$AH:$AH,0)),"YES","NO") -> NO
A20: chr3 | B20: 45867820 | C20: 45867820 | D20: C | E20: A | F20: exonic | G20: LZTFL1 | H20: stopgain SNV | I20: LZTFL1:NM_020347:exon10:c.G886T:p.E296X,LZTFL1:NM_001276378:exon12:c.G835T:p.E279X | J20: Score=361;Name=lod=39 | O20: 0.01 | P20: . | Q20: . | R20: . | S20: . | T20: 0 | U20: D | V20: . | W20: . | X20: . | Y20: . | Z20: . | AA20: 4.52 | AB20: 1.411 | AC20: 9.025 | AD20: 38 | AE20: 0/1 | AF20: 8 | AG20: Heterozygous | AH20: =A20&"_"&B20&"_"&D20&"_"&E20 -> chr3_45867820_C_A | AI20: =IF(ISNUMBER(MATCH(AH20,MM47_FINAL!$AH:$AH,0)),"YES","NO") -> NO
A21: chr3 | B21: 93624882 | C21: 93624882 | D21: C | E21: A | F21: exonic | G21: PROS1 | H21: nonsynonymous SNV | I21: PROS1:NM_000313:exon5:c.G452T:p.G151V | J21: Score=443;Name=lod=84 | K21: Score=0.948912;Name=chr3:90246336 | L21: 7.7e-05 | O21: 0 | P21: 1 | Q21: D | R21: 1 | S21: D | T21: 3.2e-05 | U21: D | V21: 3e-06 | W21: N | X21: 4.03 | Y21: high | Z21: -5.45 | AA21: 4.44 | AB21: 2.314 | AC21: 17.2572 | AD21: 31 | AE21: 0/1 | AF21: 8 | AG21: Heterozygous | AH21: =A21&"_"&B21&"_"&D21&"_"&E21 -> chr3_93624882_C_A | AI21: =IF(ISNUMBER(MATCH(AH21,MM47_FINAL!$AH:$AH,0)),"YES","NO") -> NO
A22: chr3 | B22: 121489220 | C22: 121489220 | D22: A | E22: T | F22: exonic | G22: IQCB1 | H22: stopgain SNV | I22: IQCB1:NM_001023571:exon12:c.T1370A:p.L457X,IQCB1:NM_001023570:exon15:c.T1769A:p.L590X | J22: Score=420;Name=lod=68 | O22: 1 | P22: . | Q22: . | R22: . | S22: . | T22: 0.000299 | U22: D | V22: 0.999719 | W22: D | X22: . | Y22: . | Z22: . | AA22: 5.49 | AB22: 2.304 | AC22: 11.909 | AD22: 36 | AE22: 0/1 | AF22: 4 | AG22: Heterozygous | AH22: =A22&"_"&B22&"_"&D22&"_"&E22 -> chr3_121489220_A_T | AI22: =IF(ISNUMBER(MATCH(AH22,MM47_FINAL!$AH:$AH,0)),"YES","NO") -> NO
A23: chr3 | B23: 121516036 | C23: 121516036 | D23: C | E23: A | F23: exonic | G23: IQCB1 | H23: stopgain SNV | I23: IQCB1:NM_001023570:exon9:c.G805T:p.E269X | J23: Score=450;Name=lod=90 | O23: 0.48 | P23: . | Q23: . | R23: . | S23: . | T23: 3e-06 | U23: D | V23: 1 | W23: A | X23: . | Y23: . | Z23: . | AA23: 2.54 | AB23: 0.787 | AC23: 6.9482 | AD23: 34 | AE23: 0/1 | AF23: 10 | AG23: Heterozygous | AH23: =A23&"_"&B23&"_"&D23&"_"&E23 -> chr3_121516036_C_A | AI23: =IF(ISNUMBER(MATCH(AH23,MM47_FINAL!$AH:$AH,0)),"YES","NO") -> NO
A24: chr3 | B24: 150690486 | C24: 150690486 | D24: G | E24: A | F24: exonic | G24: CLRN1 | H24: stopgain SNV | I24: CLRN1:NM_001195794:exon1:c.C10T:p.Q4X,CLRN1:NM_001256819:exon1:c.C10T:p.Q4X,CLRN1:NM_174878:exon1:c.C10T:p.Q4X | J24: Score=495;Name=lod=137 | O24: 0.44 | P24: . | Q24: . | R24: . | S24: . | T24: 0.001376 | U24: N | V24: 1 | W24: A | X24: . | Y24: . | Z24: . | AA24: 4.62 | AB24: 2.618 | AC24: 8.7265 | AD24: 38 | AE24: 0/1 | AF24: 22 | AG24: Heterozygous | AH24: =A24&"_"&B24&"_"&D24&"_"&E24 -> chr3_150690486_G_A | AI24: =IF(ISNUMBER(MATCH(AH24,MM47_FINAL!$AH:$AH,0)),"YES","NO") -> NO
A25: chr3 | B25: 184072350 | C25: 184072350 | D25: C | E25: T | F25: exonic | G25: CLCN2 | H25: nonsynonymous SNV | I25: CLCN2:NM_001171088:exon13:c.G1361A:p.G454D,CLCN2:NM_001171087:exon14:c.G1442A:p.G481D,CLCN2:NM_001171089:exon14:c.G1493A:p.G498D,CLCN2:NM_004366:exon14:c.G1493A:p.G498D | J25: Score=435;Name=lod=78 | O25: 0.01 | P25: 0.999 | Q25: D | R25: 0.985 | S25: D | T25: 6e-06 | U25: D | V25: . | W25: . | X25: 3.295 | Y25: medium | Z25: -2.66 | AA25: 5.02 | AB25: 2.342 | AC25: 17.9675 | AD25: 31 | AE25: 0/1 | AF25: 7 | AG25: Heterozygous | AH25: =A25&"_"&B25&"_"&D25&"_"&E25 -> chr3_184072350_C_T | AI25: =IF(ISNUMBER(MATCH(AH25,MM47_FINAL!$AH:$AH,0)),"YES","NO") -> NO
A26: chr3 | B26: 193343911 | C26: 193343911 | D26: C | E26: T | F26: exonic | G26: OPA1 | H26: stopgain SNV | I26: OPA1:NM_130833:exon5:c.C547T:p.Q183X,OPA1:NM_130835:exon6:c.C601T:p.Q201X,OPA1:NM_130836:exon6:c.C655T:p.Q219X,OPA1:NM_130837:exon7:c.C709T:p.Q237X | J26: Score=681;Name=lod=782 | O26: 1 | P26: . | Q26: . | R26: . | S26: . | T26: 0.025583 | U26: N | V26: 1 | W26: A | X26: . | Y26: . | Z26: . | AA26: 5.74 | AB26: 2.732 | AC26: 14.518 | AD26: 41 | AE26: 0/1 | AF26: 19 | AG26: Heterozygous | AH26: =A26&"_"&B26&"_"&D26&"_"&E26 -> chr3_193343911_C_T | AI26: =IF(ISNUMBER(MATCH(AH26,MM47_FINAL!$AH:$AH,0)),"YES","NO") -> NO
A27: chr3 | B27: 195968940 | C27: 195968940 | D27: C | E27: A | F27: exonic | G27: PCYT1A | H27: nonsynonymous SNV | I27: PCYT1A:NM_005017:exon8:c.G587T:p.R196M | J27: Score=666;Name=lod=676 | O27: 0 | P27: 0.996 | Q27: D | R27: 0.906 | S27: P | T27: 0 | U27: D | V27: 0.9998 | W27: D | X27: 4.54 | Y27: high | Z27: . | AA27: 5.65 | AB27: 2.685 | AC27: 18.7797 | AD27: 34 | AE27: 0/1 | AF27: 12 | AG27: Heterozygous | AH27: =A27&"_"&B27&"_"&D27&"_"&E27 -> chr3_195968940_C_A | AI27: =IF(ISNUMBER(MATCH(AH27,MM47_FINAL!$AH:$AH,0)),"YES","NO") -> NO
A28: chr3 | B28: 195968943 | C28: 195968943 | D28: T | E28: A | F28: exonic | G28: PCYT1A | H28: nonsynonymous SNV | I28: PCYT1A:NM_005017:exon8:c.A584T:p.Q195L | J28: Score=666;Name=lod=676 | O28: 0 | P28: 0.935 | Q28: P | R28: 0.605 | S28: P | T28: 0 | U28: D | V28: 0.990866 | W28: D | X28: 2.87 | Y28: medium | Z28: . | AA28: 5.65 | AB28: 2.169 | AC28: 15.1136 | AD28: 32 | AE28: 0/1 | AF28: 12 | AG28: Heterozygous | AH28: =A28&"_"&B28&"_"&D28&"_"&E28 -> chr3_195968943_T_A | AI28: =IF(ISNUMBER(MATCH(AH28,MM47_FINAL!$AH:$AH,0)),"YES","NO") -> NO
A29: chr4 | B29: 15542602 | C29: 15542602 | D29: C | E29: T | F29: exonic | G29: CC2D2A | H29: stopgain SNV | I29: CC2D2A:NM_001080522:exon18:c.C2146T:p.Q716X | J29: Score=541;Name=lod=211 | O29: 0.95 | P29: . | Q29: . | R29: . | S29: . | T29: 4e-06 | U29: D | V29: 1 | W29: A | X29: . | Y29: . | Z29: . | AA29: 4.09 | AB29: 1.207 | AC29: 15.0518 | AD29: 38 | AE29: 0/1 | AF29: 8 | AG29: Heterozygous | AH29: =A29&"_"&B29&"_"&D29&"_"&E29 -> chr4_15542602_C_T | AI29: =IF(ISNUMBER(MATCH(AH29,MM47_FINAL!$AH:$AH,0)),"YES","NO") -> NO
A30: chr5 | B30: 38458465 | C30: 38458465 | D30: G | E30: A | F30: exonic | G30: EGFLAM | H30: nonsynonymous SNV | I30: EGFLAM:NM_182801:exon4:c.G169A:p.D57N,EGFLAM:NM_182798:exon15:c.G2038A:p.D680N,EGFLAM:NM_152403:exon20:c.G2740A:p.D914N,EGFLAM:NM_001205301:exon21:c.G2764A:p.D922N | J30: Score=517;Name=lod=168 | L30: 0.000308 | N30: rs148613168 | O30: 0.06 | P30: 1 | Q30: D | R30: 1 | S30: D | T30: 0 | U30: D | V30: 0.998487 | W30: D | X30: 2.285 | Y30: medium | Z30: -1.62 | AA30: 5.46 | AB30: 2.721 | AC30: 19.6604 | AD30: 32 | AE30: 0/1 | AF30: 37 | AG30: Heterozygous | AH30: =A30&"_"&B30&"_"&D30&"_"&E30 -> chr5_38458465_G_A | AI30: =IF(ISNUMBER(MATCH(AH30,MM47_FINAL!$AH:$AH,0)),"YES","NO") -> YES
A31: chr5 | B31: 92929435 | C31: 92929435 | D31: C | E31: A | F31: exonic | G31: NR2F1 | H31: nonsynonymous SNV | I31: NR2F1:NM_005654:exon3:c.C1159A:p.Q387K | J31: Score=721;Name=lod=1133 | O31: 0.02 | P31: 0.998 | Q31: D | R31: 0.994 | S31: D | T31: 0 | U31: D | V31: 0.974882 | W31: D | X31: 1.905 | Y31: medium | Z31: -4.59 | AA31: 6.17 | AB31: 2.941 | AC31: 20.4898 | AD31: 32 | AE31: 0/1 | AF31: 17 | AG31: Heterozygous | AH31: =A31&"_"&B31&"_"&D31&"_"&E31 -> chr5_92929435_C_A | AI31: =IF(ISNUMBER(MATCH(AH31,MM47_FINAL!$AH:$AH,0)),"YES","NO") -> NO
A32: chr5 | B32: 138145869 | C32: 138145869 | D32: C | E32: G | F32: exonic | G32: CTNNA1 | H32: stopgain SNV | I32: CTNNA1:NM_001903:exon4:c.C444G:p.Y148X | J32: Score=703;Name=lod=955 | O32: . | P32: . | Q32: . | R32: . | S32: . | T32: 0 | U32: D | V32: 1 | W32: A | X32: . | Y32: . | Z32: . | AA32: 4.59 | AB32: 2.715 | AC32: 14.8511 | AD32: 37 | AE32: 0/1 | AF32: 23 | AG32: Heterozygous | AH32: =A32&"_"&B32&"_"&D32&"_"&E32 -> chr5_138145869_C_G | AI32: =IF(ISNUMBER(MATCH(AH32,MM47_FINAL!$AH:$AH,0)),"YES","NO") -> NO
A33: chr5 | B33: 138269752 | C33: 138269752 | D33: G | E33: T | F33: exonic | G33: CTNNA1 | H33: stopgain SNV | I33: CTNNA1:NM_001903:exon18:c.G2695T:p.E899X | J33: Score=509;Name=lod=156 | O33: 0 | P33: . | Q33: . | R33: . | S33: . | T33: 0 | U33: D | V33: 0.999381 | W33: D | X33: . | Y33: . | Z33: . | AA33: 4.77 | AB33: 2.488 | AC33: 17.5866 | AD33: 41 | AE33: 1/1 | AF33: 1 | AG33: Homozygous_alt | AH33: =A33&"_"&B33&"_"&D33&"_"&E33 -> chr5_138269752_G_T | AI33: =IF(ISNUMBER(MATCH(AH33,MM47_FINAL!$AH:$AH,0)),"YES","NO") -> NO
A34: chr5 | B34: 149294570 | C34: 149294570 | D34: C | E34: A | F34: exonic | G34: PDE6A | H34: stopgain SNV | I34: PDE6A:NM_000440:exon6:c.G934T:p.E312X | J34: Score=590;Name=lod=333 | O34: 0.23 | P34: . | Q34: . | R34: . | S34: . | T34: 0 | U34: D | V34: 1 | W34: A | X34: . | Y34: . | Z34: . | AA34: 5.19 | AB34: 2.578 | AC34: 16.5661 | AD34: 55 | AE34: 0/1 | AF34: 12 | AG34: Heterozygous | AH34: =A34&"_"&B34&"_"&D34&"_"&E34 -> chr5_149294570_C_A | AI34: =IF(ISNUMBER(MATCH(AH34,MM47_FINAL!$AH:$AH,0)),"YES","NO") -> NO
A35: chr5 | B35: 178419051 | C35: 178419051 | D35: C | E35: G | F35: exonic | G35: GRM6 | H35: nonsynonymous SNV | I35: GRM6:NM_000843:exon2:c.G538C:p.E180Q | J35: Score=587;Name=lod=324 | O35: 0.42 | P35: 0.975 | Q35: D | R35: 0.984 | S35: D | T35: . | U35: . | V35: 0 | W35: N | X35: 2.495 | Y35: medium | Z35: -1.49 | AA35: 5.48 | AB35: 2.746 | AC35: 17.2396 | AD35: 31 | AE35: 0/1 | AF35: 9 | AG35: Heterozygous | AH35: =A35&"_"&B35&"_"&D35&"_"&E35 -> chr5_178419051_C_G | AI35: =IF(ISNUMBER(MATCH(AH35,MM47_FINAL!$AH:$AH,0)),"YES","NO") -> NO
A36: chr6 | B36: 35478746 | C36: 35478746 | D36: C | E36: A | F36: exonic | G36: TULP1 | H36: stopgain SNV | I36: TULP1:NM_003322:exon5:c.G391T:p.E131X | O36: 0.74 | P36: . | Q36: . | R36: . | S36: . | T36: 0.911746 | U36: N | V36: 1 | W36: A | X36: . | Y36: . | Z36: . | AA36: 3.06 | AB36: 0.981 | AC36: 6.7489 | AD36: 34 | AE36: 0/1 | AF36: 14 | AG36: Heterozygous | AH36: =A36&"_"&B36&"_"&D36&"_"&E36 -> chr6_35478746_C_A | AI36: =IF(ISNUMBER(MATCH(AH36,MM47_FINAL!$AH:$AH,0)),"YES","NO") -> NO
A37: chr6 | B37: 42156367 | C37: 42156367 | D37: C | E37: A | F37: exonic | G37: GUCA1B | H37: nonsynonymous SNV | I37: GUCA1B:NM_002098:exon2:c.G310T:p.D104Y | J37: Score=674;Name=lod=731 | O37: 0 | P37: 1 | Q37: D | R37: 1 | S37: D | T37: 0 | U37: D | V37: 1 | W37: D | X37: 3.82 | Y37: high | Z37: -0.14 | AA37: 4.87 | AB37: 2.616 | AC37: 16.3185 | AD37: 31 | AE37: 0/1 | AF37: 7 | AG37: Heterozygous | AH37: =A37&"_"&B37&"_"&D37&"_"&E37 -> chr6_42156367_C_A | AI37: =IF(ISNUMBER(MATCH(AH37,MM47_FINAL!$AH:$AH,0)),"YES","NO") -> NO
A38: chr6 | B38: 121563347 | C38: 121563347 | D38: C | E38: A | F38: exonic | G38: TBC1D32 | H38: nonsynonymous SNV | I38: TBC1D32:NM_152730:exon18:c.G2157T:p.Q719H | J38: Score=659;Name=lod=636 | O38: . | P38: 1 | Q38: D | R38: 0.997 | S38: D | T38: 0 | U38: D | V38: 0.894034 | W38: D | X38: 2.295 | Y38: medium | Z38: 1.81 | AA38: 5 | AB38: 2.492 | AC38: 18.2399 | AD38: 34 | AE38: 0/1 | AF38: 12 | AG38: Heterozygous | AH38: =A38&"_"&B38&"_"&D38&"_"&E38 -> chr6_121563347_C_A | AI38: =IF(ISNUMBER(MATCH(AH38,MM47_FINAL!$AH:$AH,0)),"YES","NO") -> NO
A39: chr7 | B39: 128037029 | C39: 128037029 | D39: G | E39: C | F39: exonic | G39: IMPDH1 | H39: stopgain SNV | I39: IMPDH1:NM_001142575:exon7:c.C792G:p.Y264X,IMPDH1:NM_001142573:exon8:c.C867G:p.Y289X,IMPDH1:NM_001142574:exon8:c.C852G:p.Y284X,IMPDH1:NM_183243:exon9:c.C1014G:p.Y338X,IMPDH1:NM_001102605:exon10:c.C1092G:p.Y364X,IMPDH1:NM_001142576:exon10:c.C1023G:p.Y341X,IMPDH1:NM_000883:exon11:c.C1122G:p.Y374X | J39: Score=616;Name=lod=426 | O39: 1 | P39: . | Q39: . | R39: . | S39: . | T39: 0 | U39: D | V39: 1 | W39: A | X39: . | Y39: . | Z39: . | AA39: 0.02 | AB39: -0.051 | AC39: 8.881 | AD39: 36 | AE39: 0/1 | AF39: 8 | AG39: Heterozygous | AH39: =A39&"_"&B39&"_"&D39&"_"&E39 -> chr7_128037029_G_C | AI39: =IF(ISNUMBER(MATCH(AH39,MM47_FINAL!$AH:$AH,0)),"YES","NO") -> NO
A40: chr7 | B40: 128038580 | C40: 128038580 | D40: G | E40: A | F40: exonic | G40: IMPDH1 | H40: nonsynonymous SNV | I40: IMPDH1:NM_001142575:exon6:c.C632T:p.A211V,IMPDH1:NM_001142573:exon7:c.C707T:p.A236V,IMPDH1:NM_001142574:exon7:c.C692T:p.A231V,IMPDH1:NM_183243:exon8:c.C854T:p.A285V,IMPDH1:NM_001102605:exon9:c.C932T:p.A311V,IMPDH1:NM_001142576:exon9:c.C863T:p.A288V,IMPDH1:NM_000883:exon10:c.C962T:p.A321V | J40: Score=643;Name=lod=545 | O40: 0 | P40: 0.997 | Q40: D | R40: 0.926 | S40: D | T40: 0 | U40: D | V40: 0.999995 | W40: D | X40: 3.82 | Y40: high | Z40: -1.3 | AA40: 5.29 | AB40: 2.489 | AC40: 16.4619 | AD40: 31 | AE40: 1/1 | AF40: 1 | AG40: Homozygous_alt | AH40: =A40&"_"&B40&"_"&D40&"_"&E40 -> chr7_128038580_G_A | AI40: =IF(ISNUMBER(MATCH(AH40,MM47_FINAL!$AH:$AH,0)),"YES","NO") -> NO
...

Sheet MM47_FINAL
A1: Chr | B1: Start | C1: End | D1: Ref | E1: Alt | F1: Func.refGene | G1: Gene.refGene | H1: ExonicFunc.refGene | I1: AAChange.refGene | J1: phastConsElements46way | K1: genomicSuperDups | L1: esp6500si_all | M1: 1000g2012apr_all | N1: snp137 | O1: LJB2_SIFT | P1: LJB2_PolyPhen2_HDIV | Q1: LJB2_PP2_HDIV_Pred | R1: LJB2_PolyPhen2_HVAR | S1: LJB2_PolyPhen2_HVAR_Pred | T1: LJB2_LRT | U1: LJB2_LRT_Pred | V1: LJB2_MutationTaster | W1: LJB2_MutationTaster_Pred | X1: LJB_MutationAssessor | Y1: LJB_MutationAssessor_Pred | Z1: LJB2_FATHMM | AA1: LJB2_GERP++ | AB1: LJB2_PhyloP | AC1: LJB2_SiPhy | AD1: CADD_PHRED | AE1: GT | AF1: DP | AG1: Zygosity | AH1: Variant_ID | AI1: COMMON W/ 3347
A2: chr1 | B2: 10042664 | C2: 10042664 | D2: G | E2: T | F2: exonic | G2: NMNAT1 | H2: stopgain SNV | I2: NMNAT1:NM_022787:exon5:c.G745T:p.E249X | J2: Score=243;Name=lod=13 | O2: 1 | P2: . | Q2: . | R2: . | S2: . | T2: 0.000189 | U2: D | V2: 1 | W2: D | X2: . | Y2: . | Z2: . | AA2: 3.09 | AB2: 0.597 | AC2: 10.4801 | AD2: 34 | AE2: 1/1 | AF2: 1 | AG2: Homozygous_alt | AH2: =A2&"_"&B2&"_"&D2&"_"&E2 -> chr1_10042664_G_T | AI2: =IF(ISNUMBER(MATCH(AH2,'3347_FINAL'!$AH:$AH,0)),"YES","NO") -> NO
A3: chr1 | B3: 20412692 | C3: 20412692 | D3: C | E3: T | F3: exonic | G3: PLA2G5 | H3: stopgain SNV | I3: PLA2G5:NM_000929:exon3:c.C157T:p.R53X | M3: 0.0005 | N3: rs200954922 | O3: 0.88 | P3: . | Q3: . | R3: . | S3: . | T3: 0.458047 | U3: N | V3: 1 | W3: A | X3: . | Y3: . | Z3: . | AA3: 1.79 | AB3: 0.294 | AC3: 7.9035 | AD3: 34 | AE3: 0/1 | AF3: 8 | AG3: Heterozygous | AH3: =A3&"_"&B3&"_"&D3&"_"&E3 -> chr1_20412692_C_T | AI3: =IF(ISNUMBER(MATCH(AH3,'3347_FINAL'!$AH:$AH,0)),"YES","NO") -> NO
A4: chr1 | B4: 26769265 | C4: 26769265 | D4: T | E4: A | F4: exonic | G4: DHDDS | H4: nonsynonymous SNV | I4: DHDDS:NM_001243564:exon4:c.T224A:p.V75D,DHDDS:NM_001243565:exon4:c.T224A:p.V75D,DHDDS:NM_024887:exon4:c.T224A:p.V75D,DHDDS:NM_205861:exon4:c.T224A:p.V75D | J4: Score=596;Name=lod=353 | O4: 0 | P4: 1 | Q4: D | R4: 1 | S4: D | T4: 0 | U4: D | V4: 0.999988 | W4: D | X4: 4.32 | Y4: high | Z4: 1.06 | AA4: 5.92 | AB4: 2.266 | AC4: 15.5442 | AD4: 31 | AE4: 0/1 | AF4: 6 | AG4: Heterozygous | AH4: =A4&"_"&B4&"_"&D4&"_"&E4 -> chr1_26769265_T_A | AI4: =IF(ISNUMBER(MATCH(AH4,'3347_FINAL'!$AH:$AH,0)),"YES","NO") -> NO
A5: chr1 | B5: 68910459 | C5: 68910459 | D5: C | E5: T | F5: exonic | G5: RPE65 | H5: nonsynonymous SNV | I5: RPE65:NM_000329:exon4:c.G353A:p.R118K | J5: Score=595;Name=lod=349 | O5: . | P5: 0.998 | Q5: D | R5: 0.96 | S5: D | T5: 0 | U5: D | V5: 0.999997 | W5: D | X5: 1.43 | Y5: low | Z5: -3.42 | AA5: 4.88 | AB5: 2.545 | AC5: 18.2168 | AD5: 34 | AE5: 0/1 | AF5: 22 | AG5: Heterozygous | AH5: =A5&"_"&B5&"_"&D5&"_"&E5 -> chr1_68910459_C_T | AI5: =IF(ISNUMBER(MATCH(AH5,'3347_FINAL'!$AH:$AH,0)),"YES","NO") -> NO
A6: chr1 | B6: 150316667 | C6: 150316667 | D6: G | E6: T | F6: exonic | G6: PRPF3 | H6: stopgain SNV | I6: PRPF3:NM_004698:exon11:c.G1456T:p.G486X | J6: Score=664;Name=lod=665 | O6: 0.01 | P6: . | Q6: . | R6: . | S6: . | T6: 0 | U6: D | V6: 1 | W6: A | X6: . | Y6: . | Z6: . | AA6: 5.82 | AB6: 2.759 | AC6: 20.1022 | AD6: 41 | AE6: 1/1 | AF6: 9 | AG6: Homozygous_alt | AH6: =A6&"_"&B6&"_"&D6&"_"&E6 -> chr1_150316667_G_T | AI6: =IF(ISNUMBER(MATCH(AH6,'3347_FINAL'!$AH:$AH,0)),"YES","NO") -> NO
A7: chr1 | B7: 156145389 | C7: 156145389 | D7: G | E7: A | F7: exonic | G7: SEMA4A | H7: stopgain SNV | I7: SEMA4A:NM_001193302:exon12:c.G1239A:p.W413X,SEMA4A:NM_001193300:exon14:c.G1635A:p.W545X,SEMA4A:NM_001193301:exon14:c.G1635A:p.W545X,SEMA4A:NM_022367:exon14:c.G1635A:p.W545X | O7: 0.04 | P7: . | Q7: . | R7: . | S7: . | T7: 0.282915 | U7: N | V7: 1 | W7: A | X7: . | Y7: . | Z7: . | AA7: 3.62 | AB7: 1.107 | AC7: 11.1226 | AD7: 36 | AE7: 0/1 | AF7: 9 | AG7: Heterozygous | AH7: =A7&"_"&B7&"_"&D7&"_"&E7 -> chr1_156145389_G_A | AI7: =IF(ISNUMBER(MATCH(AH7,'3347_FINAL'!$AH:$AH,0)),"YES","NO") -> NO
A8: chr1 | B8: 185833602 | C8: 185833602 | D8: G | E8: A | F8: exonic | G8: HMCN1 | H8: nonsynonymous SNV | I8: HMCN1:NM_031935:exon3:c.G340A:p.G114S | J8: Score=633;Name=lod=498 | O8: . | P8: 1 | Q8: D | R8: 1 | S8: D | T8: 0 | U8: D | V8: 0.999985 | W8: D | X8: 3.265 | Y8: medium | Z8: -4.57 | AA8: 5.43 | AB8: 2.533 | AC8: 19.2402 | AD8: 33 | AE8: 0/1 | AF8: 19 | AG8: Heterozygous | AH8: =A8&"_"&B8&"_"&D8&"_"&E8 -> chr1_185833602_G_A | AI8: =IF(ISNUMBER(MATCH(AH8,'3347_FINAL'!$AH:$AH,0)),"YES","NO") -> NO
A9: chr1 | B9: 185833603 | C9: 185833603 | D9: G | E9: A | F9: exonic | G9: HMCN1 | H9: nonsynonymous SNV | I9: HMCN1:NM_031935:exon3:c.G341A:p.G114D | J9: Score=633;Name=lod=498 | O9: 0 | P9: 1 | Q9: D | R9: 1 | S9: D | T9: 0 | U9: D | V9: 0.999988 | W9: D | X9: 2.92 | Y9: medium | Z9: -4.59 | AA9: 5.43 | AB9: 2.533 | AC9: 19.2402 | AD9: 33 | AE9: 0/1 | AF9: 19 | AG9: Heterozygous | AH9: =A9&"_"&B9&"_"&D9&"_"&E9 -> chr1_185833603_G_A | AI9: =IF(ISNUMBER(MATCH(AH9,'3347_FINAL'!$AH:$AH,0)),"YES","NO") -> NO
A10: chr1 | B10: 185833605 | C10: 185833605 | D10: G | E10: T | F10: exonic | G10: HMCN1 | H10: nonsynonymous SNV | I10: HMCN1:NM_031935:exon3:c.G343T:p.G115C | J10: Score=633;Name=lod=498 | O10: 0 | P10: 1 | Q10: D | R10: 1 | S10: D | T10: 0 | U10: D | V10: 0.999985 | W10: D | X10: 3.3 | Y10: medium | Z10: 0.6 | AA10: 5.43 | AB10: 2.533 | AC10: 19.2402 | AD10: 32 | AE10: 0/1 | AF10: 19 | AG10: Heterozygous | AH10: =A10&"_"&B10&"_"&D10&"_"&E10 -> chr1_185833605_G_T | AI10: =IF(ISNUMBER(MATCH(AH10,'3347_FINAL'!$AH:$AH,0)),"YES","NO") -> NO
A11: chr1 | B11: 185891515 | C11: 185891515 | D11: C | E11: A | F11: exonic | G11: HMCN1 | H11: stopgain SNV | I11: HMCN1:NM_031935:exon7:c.C905A:p.S302X | J11: Score=426;Name=lod=72 | O11: 1 | P11: . | Q11: . | R11: . | S11: . | T11: 0 | U11: D | V11: 1 | W11: A | X11: . | Y11: . | Z11: . | AA11: 5.43 | AB11: 2.527 | AC11: 19.2454 | AD11: 38 | AE11: 0/1 | AF11: 9 | AG11: Heterozygous | AH11: =A11&"_"&B11&"_"&D11&"_"&E11 -> chr1_185891515_C_A | AI11: =IF(ISNUMBER(MATCH(AH11,'3347_FINAL'!$AH:$AH,0)),"YES","NO") -> NO
A12: chr1 | B12: 185958690 | C12: 185958690 | D12: C | E12: A | F12: exonic | G12: HMCN1 | H12: stopgain SNV | I12: HMCN1:NM_031935:exon21:c.C3119A:p.S1040X | J12: Score=389;Name=lod=51 | O12: 1 | P12: . | Q12: . | R12: . | S12: . | T12: 0 | U12: D | V12: 1 | W12: A | X12: . | Y12: . | Z12: . | AA12: 5.45 | AB12: 2.55 | AC12: 19.3079 | AD12: 39 | AE12: 0/1 | AF12: 12 | AG12: Heterozygous | AH12: =A12&"_"&B12&"_"&D12&"_"&E12 -> chr1_185958690_C_A | AI12: =IF(ISNUMBER(MATCH(AH12,'3347_FINAL'!$AH:$AH,0)),"YES","NO") -> NO
A13: chr1 | B13: 196712649 | C13: 196712649 | D13: T | E13: A | F13: exonic | G13: CFH | H13: stopgain SNV | I13: CFH:NM_000186:exon20:c.T3201A:p.Y1067X | K13: Score=0.977931;Name=chr1:196796319 | O13: 1 | P13: . | Q13: . | R13: . | S13: . | T13: . | U13: . | V13: 1 | W13: A | X13: . | Y13: . | Z13: . | AA13: -0.0824 | AB13: 0.018 | AC13: 7.6142 | AD13: 34 | AE13: 1/1 | AF13: 2 | AG13: Homozygous_alt | AH13: =A13&"_"&B13&"_"&D13&"_"&E13 -> chr1_196712649_T_A | AI13: =IF(ISNUMBER(MATCH(AH13,'3347_FINAL'!$AH:$AH,0)),"YES","NO") -> NO
A14: chr1 | B14: 211847722 | C14: 211847722 | D14: C | E14: T | F14: exonic | G14: NEK2 | H14: nonsynonymous SNV | I14: NEK2:NM_001204182:exon2:c.G230A:p.R77Q,NEK2:NM_001204183:exon2:c.G230A:p.R77Q,NEK2:NM_002497:exon2:c.G230A:p.R77Q | J14: Score=638;Name=lod=521 | O14: 0.19 | P14: 0.998 | Q14: D | R14: 0.906 | S14: P | T14: 0 | U14: D | V14: 0.999691 | W14: D | X14: 0.055 | Y14: neutral | Z14: 1.12 | AA14: 4.41 | AB14: 2.153 | AC14: 17.3875 | AD14: 34 | AE14: 0/1 | AF14: 13 | AG14: Heterozygous | AH14: =A14&"_"&B14&"_"&D14&"_"&E14 -> chr1_211847722_C_T | AI14: =IF(ISNUMBER(MATCH(AH14,'3347_FINAL'!$AH:$AH,0)),"YES","NO") -> NO
A15: chr1 | B15: 215812521 | C15: 215812521 | D15: G | E15: A | F15: exonic | G15: USH2A | H15: stopgain SNV | I15: USH2A:NM_206933:exon69:c.C15028T:p.Q5010X | J15: Score=346;Name=lod=34 | O15: 0.99 | P15: . | Q15: . | R15: . | S15: . | T15: 0.035248 | U15: U | V15: 1 | W15: A | X15: . | Y15: . | Z15: . | AA15: 4.23 | AB15: 2.412 | AC15: 8.0029 | AD15: 40 | AE15: 0/1 | AF15: 16 | AG15: Heterozygous | AH15: =A15&"_"&B15&"_"&D15&"_"&E15 -> chr1_215812521_G_A | AI15: =IF(ISNUMBER(MATCH(AH15,'3347_FINAL'!$AH:$AH,0)),"YES","NO") -> NO
A16: chr2 | B16: 27275780 | C16: 27275780 | D16: G | E16: A | F16: splicing | G16: AGBL5 | J16: Score=633;Name=lod=497 | AD16: 35 | AE16: 0/1 | AF16: 5 | AG16: Heterozygous | AH16: =A16&"_"&B16&"_"&D16&"_"&E16 -> chr2_27275780_G_A | AI16: =IF(ISNUMBER(MATCH(AH16,'3347_FINAL'!$AH:$AH,0)),"YES","NO") -> NO
A17: chr2 | B17: 27280242 | C17: 27280242 | D17: G | E17: A | F17: exonic | G17: AGBL5 | H17: nonsynonymous SNV | I17: AGBL5:NM_001035507:exon9:c.G1607A:p.G536E,AGBL5:NM_021831:exon9:c.G1607A:p.G536E | J17: Score=670;Name=lod=702 | O17: 0.1 | P17: 1 | Q17: D | R17: 1 | S17: D | T17: 0 | U17: D | V17: 0.981601 | W17: D | X17: 1.98 | Y17: medium | Z17: 1.98 | AA17: 6.16 | AB17: 2.937 | AC17: 20.4549 | AD17: 31 | AE17: 0/1 | AF17: 8 | AG17: Heterozygous | AH17: =A17&"_"&B17&"_"&D17&"_"&E17 -> chr2_27280242_G_A | AI17: =IF(ISNUMBER(MATCH(AH17,'3347_FINAL'!$AH:$AH,0)),"YES","NO") -> NO
A18: chr2 | B18: 56145033 | C18: 56145033 | D18: G | E18: T | F18: exonic | G18: EFEMP1 | H18: stopgain SNV | I18: EFEMP1:NM_001039349:exon4:c.C284A:p.S95X,EFEMP1:NM_001039348:exon5:c.C284A:p.S95X | O18: 0.79 | P18: . | Q18: . | R18: . | S18: . | T18: 0.166147 | U18: N | V18: 1 | W18: A | X18: . | Y18: . | Z18: . | AA18: 4.08 | AB18: 0.834 | AC18: 11.5657 | AD18: 34 | AE18: 0/1 | AF18: 9 | AG18: Heterozygous | AH18: =A18&"_"&B18&"_"&D18&"_"&E18 -> chr2_56145033_G_T | AI18: =IF(ISNUMBER(MATCH(AH18,'3347_FINAL'!$AH:$AH,0)),"YES","NO") -> NO
A19: chr2 | B19: 73777486 | C19: 73777486 | D19: G | E19: T | F19: exonic | G19: ALMS1 | H19: stopgain SNV | I19: ALMS1:NM_015120:exon13:c.G9997T:p.E3333X | J19: Score=461;Name=lod=100 | O19: 0 | P19: . | Q19: . | R19: . | S19: . | T19: 0.000125 | U19: D | V19: 1 | W19: A | X19: . | Y19: . | Z19: . | AA19: 5.83 | AB19: 2.762 | AC19: 15.6048 | AD19: 46 | AE19: 0/1 | AF19: 15 | AG19: Heterozygous | AH19: =A19&"_"&B19&"_"&D19&"_"&E19 -> chr2_73777486_G_T | AI19: =IF(ISNUMBER(MATCH(AH19,'3347_FINAL'!$AH:$AH,0)),"YES","NO") -> NO
A20: chr2 | B20: 73799895 | C20: 73799895 | D20: C | E20: T | F20: exonic | G20: ALMS1 | H20: nonsynonymous SNV | I20: ALMS1:NM_015120:exon16:c.C10888T:p.R3630C | J20: Score=475;Name=lod=114 | O20: 0 | P20: 1 | Q20: D | R20: 0.998 | S20: D | T20: 0.000282 | U20: D | V20: 0.306209 | W20: N | X20: 1.445 | Y20: low | Z20: 2.17 | AA20: 5.48 | AB20: 2.588 | AC20: 16.8459 | AD20: 32 | AE20: 0/1 | AF20: 7 | AG20: Heterozygous | AH20: =A20&"_"&B20&"_"&D20&"_"&E20 -> chr2_73799895_C_T | AI20: =IF(ISNUMBER(MATCH(AH20,'3347_FINAL'!$AH:$AH,0)),"YES","NO") -> NO
A21: chr2 | B21: 96944370 | C21: 96944370 | D21: G | E21: T | F21: exonic | G21: SNRNP200 | H21: stopgain SNV | I21: SNRNP200:NM_014014:exon38:c.C5403A:p.C1801X | J21: Score=636;Name=lod=513 | O21: 1 | P21: . | Q21: . | R21: . | S21: . | T21: 0 | U21: D | V21: 1 | W21: A | X21: . | Y21: . | Z21: . | AA21: 1.93 | AB21: 0.453 | AC21: 10.9518 | AD21: 36 | AE21: 0/1 | AF21: 8 | AG21: Heterozygous | AH21: =A21&"_"&B21&"_"&D21&"_"&E21 -> chr2_96944370_G_T | AI21: =IF(ISNUMBER(MATCH(AH21,'3347_FINAL'!$AH:$AH,0)),"YES","NO") -> NO
A22: chr2 | B22: 110901146 | C22: 110901146 | D22: A | E22: T | F22: exonic | G22: NPHP1 | H22: stopgain SNV | I22: NPHP1:NM_001128179:exon14:c.T1313A:p.L438X,NPHP1:NM_000272:exon16:c.T1670A:p.L557X,NPHP1:NM_001128178:exon16:c.T1502A:p.L501X,NPHP1:NM_207181:exon16:c.T1667A:p.L556X | J22: Score=487;Name=lod=127 | O22: 1 | P22: . | Q22: . | R22: . | S22: . | T22: 0.007176 | U22: N | V22: 1 | W22: A | X22: . | Y22: . | Z22: . | AA22: 4.9 | AB22: 1.107 | AC22: 10.5079 | AD22: 37 | AE22: 0/1 | AF22: 22 | AG22: Heterozygous | AH22: =A22&"_"&B22&"_"&D22&"_"&E22 -> chr2_110901146_A_T | AI22: =IF(ISNUMBER(MATCH(AH22,'3347_FINAL'!$AH:$AH,0)),"YES","NO") -> NO
A23: chr3 | B23: 3189232 | C23: 3189232 | D23: A | E23: T | F23: exonic | G23: TRNT1 | H23: stopgain SNV | I23: TRNT1:NM_182916:exon7:c.A901T:p.K301X | J23: Score=612;Name=lod=408 | O23: 1 | P23: . | Q23: . | R23: . | S23: . | T23: 0.011541 | U23: N | V23: 1 | W23: A | X23: . | Y23: . | Z23: . | AA23: 5.64 | AB23: 2.155 | AC23: 10.7452 | AD23: 43 | AE23: 0/1 | AF23: 8 | AG23: Heterozygous | AH23: =A23&"_"&B23&"_"&D23&"_"&E23 -> chr3_3189232_A_T | AI23: =IF(ISNUMBER(MATCH(AH23,'3347_FINAL'!$AH:$AH,0)),"YES","NO") -> NO
A24: chr3 | B24: 27439683 | C24: 27439683 | D24: C | E24: G | F24: exonic | G24: SLC4A7 | H24: nonsynonymous SNV | I24: SLC4A7:NM_001258379:exon16:c.G2205C:p.K735N,SLC4A7:NM_001258380:exon16:c.G2190C:p.K730N,SLC4A7:NM_003615:exon17:c.G2562C:p.K854N | J24: Score=679;Name=lod=768 | O24: 0.23 | P24: 0.991 | Q24: D | R24: 0.968 | S24: D | T24: 0 | U24: D | V24: 0.961686 | W24: D | X24: 2.125 | Y24: medium | Z24: -2.13 | AA24: 5.56 | AB24: 2.615 | AC24: 19.5319 | AD24: 36 | AE24: 0/1 | AF24: 14 | AG24: Heterozygous | AH24: =A24&"_"&B24&"_"&D24&"_"&E24 -> chr3_27439683_C_G | AI24: =IF(ISNUMBER(MATCH(AH24,'3347_FINAL'!$AH:$AH,0)),"YES","NO") -> NO
A25: chr3 | B25: 121509037 | C25: 121509037 | D25: C | E25: A | F25: exonic | G25: IQCB1 | H25: stopgain SNV | I25: IQCB1:NM_001023571:exon8:c.G613T:p.E205X,IQCB1:NM_001023570:exon11:c.G1012T:p.E338X | O25: 0.74 | P25: . | Q25: . | R25: . | S25: . | T25: 0.07042 | U25: N | V25: 1 | W25: A | X25: . | Y25: . | Z25: . | AA25: -0.425 | AB25: -0.139 | AC25: 4.2475 | AD25: 31 | AE25: 0/1 | AF25: 16 | AG25: Heterozygous | AH25: =A25&"_"&B25&"_"&D25&"_"&E25 -> chr3_121509037_C_A | AI25: =IF(ISNUMBER(MATCH(AH25,'3347_FINAL'!$AH:$AH,0)),"YES","NO") -> NO
A26: chr3 | B26: 170219056 | C26: 170219056 | D26: C | E26: T | F26: exonic | G26: SLC7A14 | H26: nonsynonymous SNV | I26: SLC7A14:NM_020949:exon3:c.G383A:p.G128E | J26: Score=458;Name=lod=97 | O26: 0 | P26: 1 | Q26: D | R26: 1 | S26: D | T26: 0 | U26: D | V26: 0.999852 | W26: D | X26: 4.305 | Y26: high | Z26: -2.69 | AA26: 5.46 | AB26: 2.715 | AC26: 19.6608 | AD26: 31 | AE26: 0/1 | AF26: 11 | AG26: Heterozygous | AH26: =A26&"_"&B26&"_"&D26&"_"&E26 -> chr3_170219056_C_T | AI26: =IF(ISNUMBER(MATCH(AH26,'3347_FINAL'!$AH:$AH,0)),"YES","NO") -> NO
A27: chr4 | B27: 15504111 | C27: 15504111 | D27: C | E27: T | F27: exonic | G27: CC2D2A | H27: nonsynonymous SNV | I27: CC2D2A:NM_001080522:exon6:c.C307T:p.R103C | J27: Score=567;Name=lod=268 | O27: 0 | P27: 1 | Q27: D | R27: 1 | S27: D | T27: 1.4e-05 | U27: D | V27: 0.998054 | W27: D | X27: 2.32 | Y27: medium | Z27: -1.12 | AA27: 4.64 | AB27: 2.616 | AC27: 14.3659 | AD27: 32 | AE27: 0/1 | AF27: 6 | AG27: Heterozygous | AH27: =A27&"_"&B27&"_"&D27&"_"&E27 -> chr4_15504111_C_T | AI27: =IF(ISNUMBER(MATCH(AH27,'3347_FINAL'!$AH:$AH,0)),"YES","NO") -> NO
A28: chr4 | B28: 110790980 | C28: 110790980 | D28: G | E28: T | F28: exonic | G28: LRIT3 | H28: nonsynonymous SNV | I28: LRIT3:NM_198506:exon4:c.C1075T:p.P359S | O28: 0.82 | P28: . | Q28: . | R28: . | S28: . | T28: 0.832232 | U28: N | V28: 1 | W28: D | X28: . | Y28: . | Z28: . | AA28: 4.64 | AB28: 2.116 | AC28: 17.5281 | AD28: 35 | AE28: 0/1 | AF28: 11 | AG28: Heterozygous | AH28: =A28&"_"&B28&"_"&D28&"_"&E28 -> chr4_110790980_G_T | AI28: =IF(ISNUMBER(MATCH(AH28,'3347_FINAL'!$AH:$AH,0)),"YES","NO") -> NO
A29: chr5 | B29: 38458465 | C29: 38458465 | D29: G | E29: A | F29: exonic | G29: EGFLAM | H29: nonsynonymous SNV | I29: EGFLAM:NM_182801:exon4:c.G169A:p.D57N,EGFLAM:NM_182798:exon15:c.G2038A:p.D680N,EGFLAM:NM_152403:exon20:c.G2740A:p.D914N,EGFLAM:NM_001205301:exon21:c.G2764A:p.D922N | J29: Score=517;Name=lod=168 | L29: 0.000308 | N29: rs148613168 | O29: 0.06 | P29: 1 | Q29: D | R29: 1 | S29: D | T29: 0 | U29: D | V29: 0.998487 | W29: D | X29: 2.285 | Y29: medium | Z29: -1.62 | AA29: 5.46 | AB29: 2.721 | AC29: 19.6604 | AD29: 32 | AE29: 0/1 | AF29: 8 | AG29: Heterozygous | AH29: =A29&"_"&B29&"_"&D29&"_"&E29 -> chr5_38458465_G_A | AI29: =IF(ISNUMBER(MATCH(AH29,'3347_FINAL'!$AH:$AH,0)),"YES","NO") -> YES
A30: chr5 | B30: 138260348 | C30: 138260348 | D30: G | E30: T | F30: exonic | G30: CTNNA1 | H30: stopgain SNV | I30: CTNNA1:NM_001903:exon12:c.G1696T:p.G566X | J30: Score=640;Name=lod=533 | O30: 0.1 | P30: . | Q30: . | R30: . | S30: . | T30: 0 | U30: D | V30: 1 | W30: A | X30: . | Y30: . | Z30: . | AA30: 5.66 | AB30: 2.832 | AC30: 19.7203 | AD30: 42 | AE30: 1/1 | AF30: 2 | AG30: Homozygous_alt | AH30: =A30&"_"&B30&"_"&D30&"_"&E30 -> chr5_138260348_G_T | AI30: =IF(ISNUMBER(MATCH(AH30,'3347_FINAL'!$AH:$AH,0)),"YES","NO") -> NO
A31: chr6 | B31: 70978514 | C31: 70978514 | D31: C | E31: T | F31: exonic | G31: COL9A1 | H31: nonsynonymous SNV | I31: COL9A1:NM_078485:exon11:c.G551A:p.G184D,COL9A1:NM_001851:exon17:c.G1280A:p.G427D | J31: Score=537;Name=lod=203 | O31: 0 | P31: 1 | Q31: D | R31: 0.998 | S31: D | T31: 0 | U31: D | V31: 0.999368 | W31: D | X31: 4.435 | Y31: high | Z31: -5.17 | AA31: 5.54 | AB31: 2.598 | AC31: 16.4154 | AD31: 31 | AE31: 0/1 | AF31: 12 | AG31: Heterozygous | AH31: =A31&"_"&B31&"_"&D31&"_"&E31 -> chr6_70978514_C_T | AI31: =IF(ISNUMBER(MATCH(AH31,'3347_FINAL'!$AH:$AH,0)),"YES","NO") -> NO
A32: chr6 | B32: 80203467 | C32: 80203467 | D32: C | E32: T | F32: exonic | G32: LCA5 | H32: nonsynonymous SNV | I32: LCA5:NM_001122769:exon4:c.G721A:p.E241K,LCA5:NM_181714:exon5:c.G721A:p.E241K | J32: Score=333;Name=lod=30 | O32: 0.02 | P32: 0.738 | Q32: P | R32: 0.396 | S32: B | T32: 0.000335 | U32: D | V32: 0.700252 | W32: D | X32: 2.005 | Y32: medium | Z32: -0.99 | AA32: 5.42 | AB32: 2.69 | AC32: 18.1394 | AD32: 31 | AE32: 0/1 | AF32: 19 | AG32: Heterozygous | AH32: =A32&"_"&B32&"_"&D32&"_"&E32 -> chr6_80203467_C_T | AI32: =IF(ISNUMBER(MATCH(AH32,'3347_FINAL'!$AH:$AH,0)),"YES","NO") -> NO
A33: chr6 | B33: 99955383 | C33: 99955383 | D33: G | E33: A | F33: exonic | G33: USP45 | H33: stopgain SNV | I33: USP45:NM_001080481:exon4:c.C298T:p.Q100X | J33: Score=510;Name=lod=157 | O33: 0.08 | P33: . | Q33: . | R33: . | S33: . | T33: 8e-06 | U33: D | V33: 1 | W33: A | X33: . | Y33: . | Z33: . | AA33: 5.71 | AB33: 2.691 | AC33: 19.4698 | AD33: 38 | AE33: 0/1 | AF33: 8 | AG33: Heterozygous | AH33: =A33&"_"&B33&"_"&D33&"_"&E33 -> chr6_99955383_G_A | AI33: =IF(ISNUMBER(MATCH(AH33,'3347_FINAL'!$AH:$AH,0)),"YES","NO") -> NO
A34: chr6 | B34: 121481156 | C34: 121481156 | D34: C | E34: A | F34: exonic | G34: TBC1D32 | H34: nonsynonymous SNV | I34: TBC1D32:NM_152730:exon24:c.G2773T:p.D925Y | J34: Score=355;Name=lod=37 | O34: . | P34: 0.976 | Q34: D | R34: 0.83 | S34: P | T34: 0.000747 | U34: D | V34: 0.96256 | W34: D | X34: 1.87 | Y34: low | Z34: 1.84 | AA34: 5.03 | AB34: 2.479 | AC34: 18.7189 | AD34: 36 | AE34: 0/1 | AF34: 17 | AG34: Heterozygous | AH34: =A34&"_"&B34&"_"&D34&"_"&E34 -> chr6_121481156_C_A | AI34: =IF(ISNUMBER(MATCH(AH34,'3347_FINAL'!$AH:$AH,0)),"YES","NO") -> NO
A35: chr6 | B35: 121481159 | C35: 121481159 | D35: G | E35: A | F35: exonic | G35: TBC1D32 | H35: stopgain SNV | I35: TBC1D32:NM_152730:exon24:c.C2770T:p.Q924X | J35: Score=355;Name=lod=37 | O35: 0.27 | P35: . | Q35: . | R35: . | S35: . | T35: 0.002744 | U35: N | V35: 1 | W35: A | X35: . | Y35: . | Z35: . | AA35: 4.14 | AB35: 1.19 | AC35: 14.9113 | AD35: 38 | AE35: 0/1 | AF35: 18 | AG35: Heterozygous | AH35: =A35&"_"&B35&"_"&D35&"_"&E35 -> chr6_121481159_G_A | AI35: =IF(ISNUMBER(MATCH(AH35,'3347_FINAL'!$AH:$AH,0)),"YES","NO") -> NO
A36: chr6 | B36: 121625919 | C36: 121625919 | D36: C | E36: A | F36: exonic | G36: TBC1D32 | H36: stopgain SNV | I36: TBC1D32:NM_152730:exon6:c.G751T:p.E251X | J36: Score=529;Name=lod=189 | O36: 0.02 | P36: . | Q36: . | R36: . | S36: . | T36: 0.000801 | U36: D | V36: 1 | W36: A | X36: . | Y36: . | Z36: . | AA36: 4.93 | AB36: 2.272 | AC36: 18.1959 | AD36: 44 | AE36: 0/1 | AF36: 6 | AG36: Heterozygous | AH36: =A36&"_"&B36&"_"&D36&"_"&E36 -> chr6_121625919_C_A | AI36: =IF(ISNUMBER(MATCH(AH36,'3347_FINAL'!$AH:$AH,0)),"YES","NO") -> NO
A37: chr7 | B37: 23205540 | C37: 23205540 | D37: C | E37: A | F37: exonic | G37: KLHL7 | H37: nonsynonymous SNV | I37: KLHL7:NM_001031710:exon8:c.C1160A:p.S387Y,KLHL7:NM_018846:exon8:c.C1016A:p.S339Y | J37: Score=636;Name=lod=514 | O37: 0 | P37: 1 | Q37: D | R37: 0.992 | S37: D | T37: 0 | U37: D | V37: 0.998978 | W37: D | X37: 1.575 | Y37: low | Z37: 1.49 | AA37: 5.77 | AB37: 2.729 | AC37: 19.9926 | AD37: 33 | AE37: 1/1 | AF37: 2 | AG37: Homozygous_alt | AH37: =A37&"_"&B37&"_"&D37&"_"&E37 -> chr7_23205540_C_A | AI37: =IF(ISNUMBER(MATCH(AH37,'3347_FINAL'!$AH:$AH,0)),"YES","NO") -> NO
A38: chr7 | B38: 33296904 | C38: 33296904 | D38: G | E38: T | F38: exonic | G38: BBS9 | H38: stopgain SNV | I38: BBS9:NM_001033604:exon6:c.G499T:p.E167X,BBS9:NM_001033605:exon6:c.G499T:p.E167X,BBS9:NM_014451:exon6:c.G499T:p.E167X,BBS9:NM_198428:exon6:c.G499T:p.E167X | J38: Score=595;Name=lod=348 | O38: 0.08 | P38: . | Q38: . | R38: . | S38: . | T38: 0 | U38: D | V38: 1 | W38: A | X38: . | Y38: . | Z38: . | AA38: 5.86 | AB38: 2.776 | AC38: 20.2019 | AD38: 39 | AE38: 0/1 | AF38: 10 | AG38: Heterozygous | AH38: =A38&"_"&B38&"_"&D38&"_"&E38 -> chr7_33296904_G_T | AI38: =IF(ISNUMBER(MATCH(AH38,'3347_FINAL'!$AH:$AH,0)),"YES","NO") -> NO
A39: chr7 | B39: 33376229 | C39: 33376229 | D39: C | E39: A | F39: exonic | G39: BBS9 | H39: stopgain SNV | I39: BBS9:NM_001033604:exon10:c.C1193A:p.S398X,BBS9:NM_001033605:exon10:c.C1193A:p.S398X,BBS9:NM_014451:exon10:c.C1193A:p.S398X,BBS9:NM_198428:exon10:c.C1193A:p.S398X | J39: Score=536;Name=lod=202 | O39: 1 | P39: . | Q39: . | R39: . | S39: . | T39: 0.065466 | U39: N | V39: 1 | W39: A | X39: . | Y39: . | Z39: . | AA39: 3.71 | AB39: 0.679 | AC39: 10.7203 | AD39: 36 | AE39: 0/1 | AF39: 8 | AG39: Heterozygous | AH39: =A39&"_"&B39&"_"&D39&"_"&E39 -> chr7_33376229_C_A | AI39: =IF(ISNUMBER(MATCH(AH39,'3347_FINAL'!$AH:$AH,0)),"YES","NO") -> NO
A40: chr7 | B40: 33376234 | C40: 33376234 | D40: G | E40: T | F40: exonic | G40: BBS9 | H40: nonsynonymous SNV | I40: BBS9:NM_001033604:exon10:c.G1198T:p.G400C,BBS9:NM_001033605:exon10:c.G1198T:p.G400C,BBS9:NM_014451:exon10:c.G1198T:p.G400C,BBS9:NM_198428:exon10:c.G1198T:p.G400C | J40: Score=536;Name=lod=202 | O40: 0.05 | P40: 0.796 | Q40: P | R40: 0.669 | S40: P | T40: 0.002851 | U40: N | V40: . | W40: . | X40: 1.445 | Y40: low | Z40: 0.67 | AA40: 5.54 | AB40: 2.604 | AC40: 19.4774 | AD40: 33 | AE40: 0/1 | AF40: 8 | AG40: Heterozygous | AH40: =A40&"_"&B40&"_"&D40&"_"&E40 -> chr7_33376234_G_T | AI40: =IF(ISNUMBER(MATCH(AH40,'3347_FINAL'!$AH:$AH,0)),"YES","NO") -> NO
...
